<?xml version="1.0" ?>
<!-- =================================================================================== -->
<!-- |    This document was autogenerated by xacro from krotic.xacro                   | -->
<!-- |    EDITING THIS FILE BY HAND IS NOT RECOMMENDED                                 | -->
<!-- =================================================================================== -->
<robot name="krotic" xmlns:xacro="http://www.ros.org/wiki/xacro">
  <gazebo reference="base_footprint">
    <turnGravityOff>false</turnGravityOff>
  </gazebo>
  <gazebo reference="base_link">
    <turnGravityOff>false</turnGravityOff>
    <material>Gazebo/Black</material>
  </gazebo>
  <gazebo reference="caster_wheel">
    <mu1 value="0.0"/>
    <mu2 value="0.0"/>
    <turnGravityOff>false</turnGravityOff>
    <material>Gazebo/Grey</material>
  </gazebo>
  <gazebo>
    <plugin filename="libgazebo_ros_control.so" name="gazebo_ros_control">
      <robotNamespace>/krotic</robotNamespace>
      <robotSimType>gazebo_ros_control/DefaultRobotHWSim</robotSimType>
      <legacyModeNS>true</legacyModeNS>
    </plugin>
    <plugin filename="libgazebo_ros_joint_state_publisher.so" name="joint_state_publisher">
      <jointName>right_wheel_hinge, left_wheel_hinge</jointName>
      <updateRate>10.0</updateRate>
      <alwaysOn>true</alwaysOn>
    </plugin>
  </gazebo>
  <gazebo>
    <plugin filename="libgazebo_ros_diff_drive.so" name="differential_drive_controller">
      <legacyMode>false</legacyMode>
      <rosDebugLevel>Debug</rosDebugLevel>
      <publishWheelTF>True</publishWheelTF>
      <publishTf>1</publishTf>
      <publishWheelJointState>true</publishWheelJointState>
      <alwaysOn>true</alwaysOn>
      <updateRate>100.0</updateRate>
      <leftJoint>left_wheel_hinge</leftJoint>
      <rightJoint>right_wheel_hinge</rightJoint>
      <wheelSeparation>0.32</wheelSeparation>
      <wheelDiameter>0.24</wheelDiameter>
      <broadcastTF>1</broadcastTF>
      <wheelTorque>30</wheelTorque>
      <wheelAcceleration>1.8</wheelAcceleration>
      <publishOdomTF>true</publishOdomTF>
      <odometrySource>world</odometrySource>
      <commandTopic>cmd_vel</commandTopic>
      <odometryFrame>odom</odometryFrame>
      <odometryTopic>odom</odometryTopic>
      <robotBaseFrame>base_link</robotBaseFrame>
    </plugin>
  </gazebo>
  <gazebo reference="camera">
    <material>Gazebo/Blue</material>
    <sensor name="camera1" type="camera">
      <update_rate>30.0</update_rate>
      <camera name="head">
        <horizontal_fov>1.3962634</horizontal_fov>
        <image>
          <width>800</width>
          <height>800</height>
          <format>R8G8B8</format>
        </image>
        <clip>
          <near>0.02</near>
          <far>300</far>
        </clip>
        <noise>
          <type>gaussian</type>
          <mean>0.0</mean>
          <stddev>0.007</stddev>
        </noise>
      </camera>
      <plugin filename="libgazebo_ros_camera.so" name="camera_controller">
        <alwaysOn>true</alwaysOn>
        <updateRate>0.0</updateRate>
        <cameraName>krotic/camera1</cameraName>
        <imageTopicName>image_raw</imageTopicName>
        <cameraInfoTopicName>camera_info</cameraInfoTopicName>
        <frameName>camera_link</frameName>
        <hackBaseline>0.07</hackBaseline>
        <distortionK1>0.0</distortionK1>
        <distortionK2>0.0</distortionK2>
        <distortionK3>0.0</distortionK3>
        <distortionT1>0.0</distortionT1>
        <distortionT2>0.0</distortionT2>
      </plugin>
    </sensor>
  </gazebo>
  <gazebo reference="base_sonar">
    <sensor name="TeraRanger" type="ray">
      <pose>0 0 0 0 0 0</pose>
      <visualize>true</visualize>
      <update_rate>50</update_rate>
      <ray>
        <scan>
          <horizontal>
            <samples>10</samples>
            <resolution>1</resolution>
            <min_angle>-0.14835</min_angle>
            <max_angle>0.14835</max_angle>
          </horizontal>
          <vertical>
            <samples>10</samples>
            <resolution>1</resolution>
            <min_angle>-0.14835</min_angle>
            <max_angle>0.14835</max_angle>
          </vertical>
        </scan>
        <range>
          <min>0.01</min>
          <max>2</max>
          <resolution>0.02</resolution>
        </range>
      </ray>
      <plugin filename="libgazebo_ros_range.so" name="gazebo_ros_range">
        <gaussianNoise>0.005</gaussianNoise>
        <alwaysOn>true</alwaysOn>
        <updateRate>50</updateRate>
        <topicName>sensor/sonar</topicName>
        <frameName>base_sonar</frameName>
        <radiation>INFRARED</radiation>
        <fov>0.2967</fov>
      </plugin>
    </sensor>
  </gazebo>
  <material name="black">
    <color rgba="0.0 0.0 0.0 1.0"/>
  </material>
  <material name="blue">
    <color rgba="0.0 0.0 0.8 1.0"/>
  </material>
  <material name="green">
    <color rgba="0.0 0.8 0.0 1.0"/>
  </material>
  <material name="grey">
    <color rgba="0.2 0.2 0.2 1.0"/>
  </material>
  <material name="orange">
    <color rgba="1.0 0.423529411765 0.0392156862745 1.0"/>
  </material>
  <material name="brown">
    <color rgba="0.870588235294 0.811764705882 0.764705882353 1.0"/>
  </material>
  <material name="red">
    <color rgba="0.8 0.0 0.0 1.0"/>
  </material>
  <material name="white">
    <color rgba="1.0 1.0 1.0 1.0"/>
  </material>
  <link name="base_footprint">
    <visual>
      <origin rpy="0 0 0" xyz="0 0 0"/>
      <geometry>
        <box size="0.001 0.001 0.001"/>
      </geometry>
    </visual>
  </link>
  <link name="base_link">
    <collision>
      <origin rpy="0 0 0" xyz="0 0 0"/>
      <geometry>
        <box size="0.4 0.3 0.3"/>
      </geometry>
    </collision>
    <visual>
      <origin rpy="0 0 0" xyz="0 0 0"/>
      <geometry>
        <box size="0.4 0.3 0.3"/>
      </geometry>
      <material name="orange"/>
    </visual>
    <inertial>
      <origin rpy="0 0 0" xyz="0 0 0"/>
      <mass value="10"/>
      <inertia ixx="0.15" ixy="0" ixz="0" iyy="0.208333333333" iyz="0" izz="0.208333333333"/>
    </inertial>
  </link>
  <joint name="base_footprint_joint" type="fixed">
    <origin rpy="0 0 0" xyz="0 0 0.2"/>
    <parent link="base_footprint"/>
    <child link="base_link"/>
  </joint>
  <link name="caster_wheel">
    <collision>
      <origin rpy="0 0 0" xyz="0 0 -0.14"/>
      <geometry>
        <sphere radius="0.05"/>
      </geometry>
    </collision>
    <visual>
      <origin rpy="0 0 0" xyz="0 0 -0.14"/>
      <geometry>
        <sphere radius="0.05"/>
      </geometry>
      <material name="red"/>
    </visual>
    <inertial>
      <origin xyz="0 0 0"/>
      <mass value="1"/>
      <inertia ixx="0.001" ixy="0" ixz="0" iyy="0.001" iyz="0" izz="0.001"/>
    </inertial>
  </link>
  <joint name="base_to_caster" type="fixed">
    <parent link="base_link"/>
    <child link="caster_wheel"/>
    <origin rpy="0 0 0" xyz="0.15 0 0"/>
  </joint>
  <link name="left_wheel">
    <collision>
      <origin rpy="1.57079632679 0 0" xyz="0 0 0"/>
      <geometry>
        <cylinder length="0.05" radius="0.12"/>
      </geometry>
    </collision>
    <visual>
      <origin rpy="1.57079632679 0 0" xyz="0 0 0"/>
      <geometry>
        <cylinder length="0.05" radius="0.12"/>
      </geometry>
      <material name="grey"/>
    </visual>
    <inertial>
      <mass value="1"/>
      <inertia ixx="0.00380833333333" ixy="0" ixz="0" iyy="0.00380833333333" iyz="0" izz="0.0072"/>
    </inertial>
  </link>
  <gazebo reference="left_wheel">
    <mu1 value="1.0"/>
    <mu2 value="1.0"/>
    <kp value="10000000.0"/>
    <kd value="1.0"/>
    <fdir1 value="1 0 0"/>
    <material>Gazebo/White</material>
    <turnGravityOff>false</turnGravityOff>
  </gazebo>
  <joint name="left_wheel_hinge" type="continuous">
    <parent link="base_link"/>
    <child link="left_wheel"/>
    <origin rpy="0 0 0" xyz="-0.07 0.16 -0.07"/>
    <axis rpy="0 0 0" xyz="0 1 0"/>
    <limit effort="100" velocity="100"/>
    <joint_properties damping="0.0" friction="0.0"/>
  </joint>
  <transmission name="left_trans">
    <type>transmission_interface/SimpleTransmission</type>
    <joint name="left_wheel_hinge">
      <hardwareInterface>hardware_interface/EffortJointInterface</hardwareInterface>
    </joint>
    <actuator name="leftMotor">
      <hardwareInterface>EffortJointInterface</hardwareInterface>
      <mechanicalReduction>1</mechanicalReduction>
    </actuator>
  </transmission>
  <link name="right_wheel">
    <collision>
      <origin rpy="1.57079632679 0 0" xyz="0 0 0"/>
      <geometry>
        <cylinder length="0.05" radius="0.12"/>
      </geometry>
    </collision>
    <visual>
      <origin rpy="1.57079632679 0 0" xyz="0 0 0"/>
      <geometry>
        <cylinder length="0.05" radius="0.12"/>
      </geometry>
      <material name="grey"/>
    </visual>
    <inertial>
      <mass value="1"/>
      <inertia ixx="0.00380833333333" ixy="0" ixz="0" iyy="0.00380833333333" iyz="0" izz="0.0072"/>
    </inertial>
  </link>
  <gazebo reference="right_wheel">
    <mu1 value="1.0"/>
    <mu2 value="1.0"/>
    <kp value="10000000.0"/>
    <kd value="1.0"/>
    <fdir1 value="1 0 0"/>
    <material>Gazebo/White</material>
    <turnGravityOff>false</turnGravityOff>
  </gazebo>
  <joint name="right_wheel_hinge" type="continuous">
    <parent link="base_link"/>
    <child link="right_wheel"/>
    <origin rpy="0 0 0" xyz="-0.07 -0.16 -0.07"/>
    <axis rpy="0 0 0" xyz="0 1 0"/>
    <limit effort="100" velocity="100"/>
    <joint_properties damping="0.0" friction="0.0"/>
  </joint>
  <transmission name="right_trans">
    <type>transmission_interface/SimpleTransmission</type>
    <joint name="right_wheel_hinge">
      <hardwareInterface>hardware_interface/EffortJointInterface</hardwareInterface>
    </joint>
    <actuator name="rightMotor">
      <hardwareInterface>EffortJointInterface</hardwareInterface>
      <mechanicalReduction>1</mechanicalReduction>
    </actuator>
  </transmission>
  <link name="camera">
    <collision>
      <origin rpy="0 0 0" xyz="0 0 0"/>
      <geometry>
        <box size="0.05 0.05 0.05"/>
      </geometry>
    </collision>
    <visual>
      <origin rpy="0 0 0" xyz="0 0 0"/>
      <geometry>
        <box size="0.05 0.05 0.05"/>
      </geometry>
      <material name="blue"/>
    </visual>
    <inertial>
      <mass value="0.1"/>
      <origin rpy="0 0 0" xyz="0 0 0"/>
      <inertia ixx="4.16666666667e-05" ixy="0" ixz="0" iyy="4.16666666667e-05" iyz="0" izz="4.16666666667e-05"/>
    </inertial>
  </link>
  <joint name="camera_fixed" type="fixed">
    <origin rpy="0 0 0" xyz="0.1 0.1 0.17"/>
    <parent link="base_link"/>
    <child link="camera"/>
  </joint>
  <link name="base_sonar">
    <collision>
      <origin rpy="0 0 0" xyz="0 0 0"/>
      <geometry>
        <box size="0.01 0.01 0.01"/>
      </geometry>
    </collision>
    <visual>
      <origin rpy="0 0 0" xyz="0 0 0"/>
      <geometry>
        <box size="0.01 0.01 0.01"/>
      </geometry>
    </visual>
    <inertial>
      <mass value="1e-5"/>
      <origin rpy="0 0 0" xyz="0 0 0"/>
      <inertia ixx="1e-6" ixy="0" ixz="0" iyy="1e-6" iyz="0" izz="1e-6"/>
    </inertial>
  </link>
  <joint name="sonar_joint" type="fixed">
    <axis xyz="0 1 0"/>
    <origin rpy="0 0 0" xyz="0.2 0 0.10"/>
    <parent link="base_link"/>
    <child link="base_sonar"/>
  </joint>
</robot>
